const sequelize = require("../../src/db/models/index").sequelize;
const User = require("../../src/db/models").User;

describe("User", () => {
  beforeEach(done => {
    sequelize
      .sync({ force: true })
      .then(() => {
        done();
      })
      .catch(err => {
        console.log(err);
        done();
      });
  });

  describe("#create()", () => {
    it("should create a User object with a valid email and password", done => {
      User.create({
        email: "irina67@yahoo.com",
        password: "hello"
      })
        .then(user => {
          expect(user.email).toBe("irina67@yahoo.com");
          expect(user.id).toBe(1);
          done();
        })
        .catch(err => {
          console.log(err);
          done();
        });
    });
    it("should not create a user with invalid email or password", done => {
      User.create({
        email: "irinas@yahoo.com",
        password: "hi"
      })
        .then(user => {
          // The code in this block will not be evaluated since the validation error
          // will skip it. Instead, we'll catch the error in the catch block below
          // and set the expectations there.
          done();
        })
        .catch(err => {
          expect(err.message).toContain("Error: must be a valid email");
          done();
        });
    });
    it("should not create a user with an email already taken", done => {
      User.create({
        email: "irina67@yahoo.com",
        password: "hello"
      })
        .then(user => {
          User.create({
            email: "dasha@yahoo.com",
            password: "dassha"
          })
            .then(user => {
              // the code in this block will not be evaluated since the validation error
              // will skip it. Instead, we'll catch the error in the catch block below
              // and set the expectations there
              done();
            })
            .catch(err => {
              expect(err.message).toContain("Error");
              done();
            });
          done();
        })
        .catch(err => {
          console.log(err);
          done();
        });
    });
  });
});
